[02/05/2017 03:31] ERROR red on_command_error 369: Exception in command 'stop'
Traceback (most recent call last):
  File "lib\discord\ext\commands\core.py", line 50, in wrapped
    ret = yield from coro(*args, **kwargs)
  File "C:\Bot\Red-DiscordBot\cogs\audio.py", line 1893, in stop
    await self.bot.say('Stopping...')
  File "lib\discord\ext\commands\bot.py", line 309, in _augmented_msg
    msg = yield from coro
  File "red.py", line 92, in send_message
    return await super().send_message(*args, **kwargs)
  File "lib\discord\client.py", line 1152, in send_message
    data = yield from self.http.send_message(channel_id, content, guild_id=guild_id, tts=tts, embed=embed)
  File "lib\discord\http.py", line 196, in request
    raise Forbidden(r, data)
discord.errors.Forbidden: FORBIDDEN (status code: 403): Missing Permissions
[02/05/2017 05:08] WARNING audio _play 814: I can't play URL below because it is too long. Use [p]audioset maxlength to change this.

https://www.youtube.com/watch?v=FIJ3nrdmHSY
[02/05/2017 08:34] ERROR red on_command_error 369: Exception in command 'warcraft token'
Traceback (most recent call last):
  File "lib\aiohttp\connector.py", line 601, in _create_direct_connection
    local_addr=self._local_addr)
  File "C:\Users\Administrator\AppData\Local\Programs\Python\Python35\lib\asyncio\base_events.py", line 713, in create_connection
    sock, protocol_factory, ssl, server_hostname)
  File "C:\Users\Administrator\AppData\Local\Programs\Python\Python35\lib\asyncio\base_events.py", line 736, in _create_connection_transport
    yield from waiter
  File "C:\Users\Administrator\AppData\Local\Programs\Python\Python35\lib\asyncio\futures.py", line 361, in __iter__
    yield self  # This tells Task to wait for completion.
  File "C:\Users\Administrator\AppData\Local\Programs\Python\Python35\lib\asyncio\tasks.py", line 296, in _wakeup
    future.result()
  File "C:\Users\Administrator\AppData\Local\Programs\Python\Python35\lib\asyncio\futures.py", line 274, in result
    raise self._exception
  File "C:\Users\Administrator\AppData\Local\Programs\Python\Python35\lib\asyncio\sslproto.py", line 492, in data_received
    ssldata, appdata = self._sslpipe.feed_ssldata(data)
  File "C:\Users\Administrator\AppData\Local\Programs\Python\Python35\lib\asyncio\sslproto.py", line 200, in feed_ssldata
    self._sslobj.do_handshake()
  File "C:\Users\Administrator\AppData\Local\Programs\Python\Python35\lib\ssl.py", line 633, in do_handshake
    self._sslobj.do_handshake()
ssl.SSLError: [SSL: CERTIFICATE_VERIFY_FAILED] certificate verify failed (_ssl.c:645)

The above exception was the direct cause of the following exception:

Traceback (most recent call last):
  File "lib\aiohttp\connector.py", line 304, in connect
    yield from self._create_connection(req)
  File "lib\aiohttp\connector.py", line 578, in _create_connection
    transport, proto = yield from self._create_direct_connection(req)
  File "lib\aiohttp\connector.py", line 624, in _create_direct_connection
    (req.host, req.port, exc.strerror)) from exc
aiohttp.errors.ClientOSError: [Errno 1] Can not connect to wowtoken.info:443 [[SSL: CERTIFICATE_VERIFY_FAILED] certificate verify failed (_ssl.c:645)]

The above exception was the direct cause of the following exception:

Traceback (most recent call last):
  File "C:\Bot\Red-DiscordBot\cogs\blizzard.py", line 602, in print_token
    async with aiohttp.get(url, headers=self.header) as response:
  File "lib\aiohttp\client.py", line 565, in __aenter__
    self._resp = yield from self._coro
  File "lib\aiohttp\client.py", line 198, in _request
    conn = yield from self._connector.connect(req)
  File "lib\aiohttp\connector.py", line 314, in connect
    .format(key, exc.strerror)) from exc
aiohttp.errors.ClientOSError: [Errno 1] Cannot connect to host wowtoken.info:443 ssl:True [Can not connect to wowtoken.info:443 [[SSL: CERTIFICATE_VERIFY_FAILED] certificate verify failed (_ssl.c:645)]]

During handling of the above exception, another exception occurred:

Traceback (most recent call last):
  File "lib\discord\ext\commands\core.py", line 50, in wrapped
    ret = yield from coro(*args, **kwargs)
  File "C:\Bot\Red-DiscordBot\cogs\blizzard.py", line 391, in _token_warcraft
    await self.print_token(url, realm)
  File "C:\Bot\Red-DiscordBot\cogs\blizzard.py", line 620, in print_token
    await self.bot.say("Error finding WoW token prices.")
  File "lib\discord\ext\commands\bot.py", line 309, in _augmented_msg
    msg = yield from coro
  File "red.py", line 92, in send_message
    return await super().send_message(*args, **kwargs)
  File "lib\discord\client.py", line 1145, in send_message
    channel_id, guild_id = yield from self._resolve_destination(destination)
  File "lib\discord\client.py", line 289, in _resolve_destination
    raise InvalidArgument(fmt.format(destination))
discord.errors.InvalidArgument: Destination must be Channel, PrivateChannel, User, or Object. Received NoneType
[02/05/2017 08:42] ERROR red on_command_error 369: Exception in command 'warcraft token'
Traceback (most recent call last):
  File "lib\aiohttp\connector.py", line 601, in _create_direct_connection
    local_addr=self._local_addr)
  File "C:\Users\Administrator\AppData\Local\Programs\Python\Python35\lib\asyncio\base_events.py", line 713, in create_connection
    sock, protocol_factory, ssl, server_hostname)
  File "C:\Users\Administrator\AppData\Local\Programs\Python\Python35\lib\asyncio\base_events.py", line 736, in _create_connection_transport
    yield from waiter
  File "C:\Users\Administrator\AppData\Local\Programs\Python\Python35\lib\asyncio\futures.py", line 361, in __iter__
    yield self  # This tells Task to wait for completion.
  File "C:\Users\Administrator\AppData\Local\Programs\Python\Python35\lib\asyncio\tasks.py", line 296, in _wakeup
    future.result()
  File "C:\Users\Administrator\AppData\Local\Programs\Python\Python35\lib\asyncio\futures.py", line 274, in result
    raise self._exception
  File "C:\Users\Administrator\AppData\Local\Programs\Python\Python35\lib\asyncio\sslproto.py", line 492, in data_received
    ssldata, appdata = self._sslpipe.feed_ssldata(data)
  File "C:\Users\Administrator\AppData\Local\Programs\Python\Python35\lib\asyncio\sslproto.py", line 200, in feed_ssldata
    self._sslobj.do_handshake()
  File "C:\Users\Administrator\AppData\Local\Programs\Python\Python35\lib\ssl.py", line 633, in do_handshake
    self._sslobj.do_handshake()
ssl.SSLError: [SSL: CERTIFICATE_VERIFY_FAILED] certificate verify failed (_ssl.c:645)

The above exception was the direct cause of the following exception:

Traceback (most recent call last):
  File "lib\aiohttp\connector.py", line 304, in connect
    yield from self._create_connection(req)
  File "lib\aiohttp\connector.py", line 578, in _create_connection
    transport, proto = yield from self._create_direct_connection(req)
  File "lib\aiohttp\connector.py", line 624, in _create_direct_connection
    (req.host, req.port, exc.strerror)) from exc
aiohttp.errors.ClientOSError: [Errno 1] Can not connect to wowtoken.info:443 [[SSL: CERTIFICATE_VERIFY_FAILED] certificate verify failed (_ssl.c:645)]

The above exception was the direct cause of the following exception:

Traceback (most recent call last):
  File "C:\Bot\Red-DiscordBot\cogs\blizzard.py", line 602, in print_token
    async with aiohttp.get(url, headers=self.header) as response:
  File "lib\aiohttp\client.py", line 565, in __aenter__
    self._resp = yield from self._coro
  File "lib\aiohttp\client.py", line 198, in _request
    conn = yield from self._connector.connect(req)
  File "lib\aiohttp\connector.py", line 314, in connect
    .format(key, exc.strerror)) from exc
aiohttp.errors.ClientOSError: [Errno 1] Cannot connect to host wowtoken.info:443 ssl:True [Can not connect to wowtoken.info:443 [[SSL: CERTIFICATE_VERIFY_FAILED] certificate verify failed (_ssl.c:645)]]

During handling of the above exception, another exception occurred:

Traceback (most recent call last):
  File "lib\discord\ext\commands\core.py", line 50, in wrapped
    ret = yield from coro(*args, **kwargs)
  File "C:\Bot\Red-DiscordBot\cogs\blizzard.py", line 391, in _token_warcraft
    await self.print_token(url, realm)
  File "C:\Bot\Red-DiscordBot\cogs\blizzard.py", line 620, in print_token
    await self.bot.say("Error finding WoW token prices.")
  File "lib\discord\ext\commands\bot.py", line 309, in _augmented_msg
    msg = yield from coro
  File "red.py", line 92, in send_message
    return await super().send_message(*args, **kwargs)
  File "lib\discord\client.py", line 1145, in send_message
    channel_id, guild_id = yield from self._resolve_destination(destination)
  File "lib\discord\client.py", line 289, in _resolve_destination
    raise InvalidArgument(fmt.format(destination))
discord.errors.InvalidArgument: Destination must be Channel, PrivateChannel, User, or Object. Received NoneType
[02/05/2017 20:41] ERROR red on_command_error 369: Exception in command 'playlist'
Traceback (most recent call last):
  File "lib\discord\ext\commands\core.py", line 50, in wrapped
    ret = yield from coro(*args, **kwargs)
  File "C:\Bot\Red-DiscordBot\cogs\audio.py", line 1426, in playlist
    await send_cmd_help(ctx)
  File "red.py", line 141, in send_cmd_help
    await self.send_message(ctx.message.channel, page)
  File "red.py", line 92, in send_message
    return await super().send_message(*args, **kwargs)
  File "lib\discord\client.py", line 1152, in send_message
    data = yield from self.http.send_message(channel_id, content, guild_id=guild_id, tts=tts, embed=embed)
  File "lib\discord\http.py", line 196, in request
    raise Forbidden(r, data)
discord.errors.Forbidden: FORBIDDEN (status code: 403): Missing Permissions
[02/05/2017 20:51] ERROR red on_command_error 369: Exception in command 'playlist'
Traceback (most recent call last):
  File "lib\discord\ext\commands\core.py", line 50, in wrapped
    ret = yield from coro(*args, **kwargs)
  File "C:\Bot\Red-DiscordBot\cogs\audio.py", line 1426, in playlist
    await send_cmd_help(ctx)
  File "red.py", line 141, in send_cmd_help
    await self.send_message(ctx.message.channel, page)
  File "red.py", line 92, in send_message
    return await super().send_message(*args, **kwargs)
  File "lib\discord\client.py", line 1152, in send_message
    data = yield from self.http.send_message(channel_id, content, guild_id=guild_id, tts=tts, embed=embed)
  File "lib\discord\http.py", line 196, in request
    raise Forbidden(r, data)
discord.errors.Forbidden: FORBIDDEN (status code: 403): Missing Permissions
[02/05/2017 21:09] ERROR red on_command_error 369: Exception in command 'penis'
Traceback (most recent call last):
  File "lib\discord\ext\commands\core.py", line 50, in wrapped
    ret = yield from coro(*args, **kwargs)
  File "C:\Bot\Red-DiscordBot\cogs\penis.py", line 20, in penis
    await self.bot.say("Size: " + dong)
  File "lib\discord\ext\commands\bot.py", line 309, in _augmented_msg
    msg = yield from coro
  File "red.py", line 92, in send_message
    return await super().send_message(*args, **kwargs)
  File "lib\discord\client.py", line 1152, in send_message
    data = yield from self.http.send_message(channel_id, content, guild_id=guild_id, tts=tts, embed=embed)
  File "lib\discord\http.py", line 196, in request
    raise Forbidden(r, data)
discord.errors.Forbidden: FORBIDDEN (status code: 403): Missing Permissions
[02/05/2017 21:13] ERROR red on_command_error 369: Exception in command 'stop'
Traceback (most recent call last):
  File "lib\discord\ext\commands\core.py", line 50, in wrapped
    ret = yield from coro(*args, **kwargs)
  File "C:\Bot\Red-DiscordBot\cogs\audio.py", line 1896, in stop
    await self.bot.say("You can't stop music when there are other"
  File "lib\discord\ext\commands\bot.py", line 309, in _augmented_msg
    msg = yield from coro
  File "red.py", line 92, in send_message
    return await super().send_message(*args, **kwargs)
  File "lib\discord\client.py", line 1152, in send_message
    data = yield from self.http.send_message(channel_id, content, guild_id=guild_id, tts=tts, embed=embed)
  File "lib\discord\http.py", line 196, in request
    raise Forbidden(r, data)
discord.errors.Forbidden: FORBIDDEN (status code: 403): Missing Permissions
[02/05/2017 21:13] ERROR red on_command_error 369: Exception in command 'skip'
Traceback (most recent call last):
  File "lib\discord\ext\commands\core.py", line 50, in wrapped
    ret = yield from coro(*args, **kwargs)
  File "C:\Bot\Red-DiscordBot\cogs\audio.py", line 1816, in skip
    await self.bot.reply(reply)
  File "lib\discord\ext\commands\bot.py", line 309, in _augmented_msg
    msg = yield from coro
  File "red.py", line 92, in send_message
    return await super().send_message(*args, **kwargs)
  File "lib\discord\client.py", line 1152, in send_message
    data = yield from self.http.send_message(channel_id, content, guild_id=guild_id, tts=tts, embed=embed)
  File "lib\discord\http.py", line 196, in request
    raise Forbidden(r, data)
discord.errors.Forbidden: FORBIDDEN (status code: 403): Missing Permissions
[02/05/2017 22:44] ERROR red on_command_error 369: Exception in command 'play'
Traceback (most recent call last):
  File "lib\discord\ext\commands\core.py", line 50, in wrapped
    ret = yield from coro(*args, **kwargs)
  File "C:\Bot\Red-DiscordBot\cogs\audio.py", line 1338, in play
    await ctx.invoke(self._queue, url=url)
  File "lib\discord\ext\commands\context.py", line 112, in invoke
    ret = yield from command.callback(*arguments, **kwargs)
  File "C:\Bot\Red-DiscordBot\cogs\audio.py", line 1665, in _queue
    await self.bot.say("Queued.")
  File "lib\discord\ext\commands\bot.py", line 309, in _augmented_msg
    msg = yield from coro
  File "red.py", line 92, in send_message
    return await super().send_message(*args, **kwargs)
  File "lib\discord\client.py", line 1152, in send_message
    data = yield from self.http.send_message(channel_id, content, guild_id=guild_id, tts=tts, embed=embed)
  File "lib\discord\http.py", line 196, in request
    raise Forbidden(r, data)
discord.errors.Forbidden: FORBIDDEN (status code: 403): Missing Permissions
[02/05/2017 22:45] ERROR red on_command_error 369: Exception in command 'playlist'
Traceback (most recent call last):
  File "lib\discord\ext\commands\core.py", line 50, in wrapped
    ret = yield from coro(*args, **kwargs)
  File "C:\Bot\Red-DiscordBot\cogs\audio.py", line 1426, in playlist
    await send_cmd_help(ctx)
  File "red.py", line 141, in send_cmd_help
    await self.send_message(ctx.message.channel, page)
  File "red.py", line 92, in send_message
    return await super().send_message(*args, **kwargs)
  File "lib\discord\client.py", line 1152, in send_message
    data = yield from self.http.send_message(channel_id, content, guild_id=guild_id, tts=tts, embed=embed)
  File "lib\discord\http.py", line 196, in request
    raise Forbidden(r, data)
discord.errors.Forbidden: FORBIDDEN (status code: 403): Missing Permissions
[02/05/2017 22:45] ERROR red on_command_error 369: Exception in command 'skip'
Traceback (most recent call last):
  File "lib\discord\ext\commands\core.py", line 50, in wrapped
    ret = yield from coro(*args, **kwargs)
  File "C:\Bot\Red-DiscordBot\cogs\audio.py", line 1816, in skip
    await self.bot.reply(reply)
  File "lib\discord\ext\commands\bot.py", line 309, in _augmented_msg
    msg = yield from coro
  File "red.py", line 92, in send_message
    return await super().send_message(*args, **kwargs)
  File "lib\discord\client.py", line 1152, in send_message
    data = yield from self.http.send_message(channel_id, content, guild_id=guild_id, tts=tts, embed=embed)
  File "lib\discord\http.py", line 196, in request
    raise Forbidden(r, data)
discord.errors.Forbidden: FORBIDDEN (status code: 403): Missing Permissions
[02/05/2017 23:11] ERROR red on_command_error 369: Exception in command 'penis'
Traceback (most recent call last):
  File "lib\discord\ext\commands\core.py", line 50, in wrapped
    ret = yield from coro(*args, **kwargs)
  File "C:\Bot\Red-DiscordBot\cogs\penis.py", line 20, in penis
    await self.bot.say("Size: " + dong)
  File "lib\discord\ext\commands\bot.py", line 309, in _augmented_msg
    msg = yield from coro
  File "red.py", line 92, in send_message
    return await super().send_message(*args, **kwargs)
  File "lib\discord\client.py", line 1152, in send_message
    data = yield from self.http.send_message(channel_id, content, guild_id=guild_id, tts=tts, embed=embed)
  File "lib\discord\http.py", line 196, in request
    raise Forbidden(r, data)
discord.errors.Forbidden: FORBIDDEN (status code: 403): Missing Permissions
[03/05/2017 03:05] ERROR red on_command_error 369: Exception in command 'skip'
Traceback (most recent call last):
  File "lib\discord\ext\commands\core.py", line 50, in wrapped
    ret = yield from coro(*args, **kwargs)
  File "C:\Bot\Red-DiscordBot\cogs\audio.py", line 1816, in skip
    await self.bot.reply(reply)
  File "lib\discord\ext\commands\bot.py", line 309, in _augmented_msg
    msg = yield from coro
  File "red.py", line 92, in send_message
    return await super().send_message(*args, **kwargs)
  File "lib\discord\client.py", line 1152, in send_message
    data = yield from self.http.send_message(channel_id, content, guild_id=guild_id, tts=tts, embed=embed)
  File "lib\discord\http.py", line 196, in request
    raise Forbidden(r, data)
discord.errors.Forbidden: FORBIDDEN (status code: 403): Missing Permissions
[03/05/2017 03:05] ERROR red on_command_error 369: Exception in command 'queue'
Traceback (most recent call last):
  File "lib\discord\ext\commands\core.py", line 50, in wrapped
    ret = yield from coro(*args, **kwargs)
  File "C:\Bot\Red-DiscordBot\cogs\audio.py", line 1630, in _queue
    return await self._queue_list(ctx)
  File "C:\Bot\Red-DiscordBot\cogs\audio.py", line 1674, in _queue_list
    await self.bot.say("Nothing queued on this server.")
  File "lib\discord\ext\commands\bot.py", line 309, in _augmented_msg
    msg = yield from coro
  File "red.py", line 92, in send_message
    return await super().send_message(*args, **kwargs)
  File "lib\discord\client.py", line 1152, in send_message
    data = yield from self.http.send_message(channel_id, content, guild_id=guild_id, tts=tts, embed=embed)
  File "lib\discord\http.py", line 196, in request
    raise Forbidden(r, data)
discord.errors.Forbidden: FORBIDDEN (status code: 403): Missing Permissions
[03/05/2017 04:44] ERROR red on_command_error 369: Exception in command 'warcraft token'
Traceback (most recent call last):
  File "lib\aiohttp\connector.py", line 601, in _create_direct_connection
    local_addr=self._local_addr)
  File "C:\Users\Administrator\AppData\Local\Programs\Python\Python35\lib\asyncio\base_events.py", line 713, in create_connection
    sock, protocol_factory, ssl, server_hostname)
  File "C:\Users\Administrator\AppData\Local\Programs\Python\Python35\lib\asyncio\base_events.py", line 736, in _create_connection_transport
    yield from waiter
  File "C:\Users\Administrator\AppData\Local\Programs\Python\Python35\lib\asyncio\futures.py", line 361, in __iter__
    yield self  # This tells Task to wait for completion.
  File "C:\Users\Administrator\AppData\Local\Programs\Python\Python35\lib\asyncio\tasks.py", line 296, in _wakeup
    future.result()
  File "C:\Users\Administrator\AppData\Local\Programs\Python\Python35\lib\asyncio\futures.py", line 274, in result
    raise self._exception
  File "C:\Users\Administrator\AppData\Local\Programs\Python\Python35\lib\asyncio\sslproto.py", line 492, in data_received
    ssldata, appdata = self._sslpipe.feed_ssldata(data)
  File "C:\Users\Administrator\AppData\Local\Programs\Python\Python35\lib\asyncio\sslproto.py", line 200, in feed_ssldata
    self._sslobj.do_handshake()
  File "C:\Users\Administrator\AppData\Local\Programs\Python\Python35\lib\ssl.py", line 633, in do_handshake
    self._sslobj.do_handshake()
ssl.SSLError: [SSL: CERTIFICATE_VERIFY_FAILED] certificate verify failed (_ssl.c:645)

The above exception was the direct cause of the following exception:

Traceback (most recent call last):
  File "lib\aiohttp\connector.py", line 304, in connect
    yield from self._create_connection(req)
  File "lib\aiohttp\connector.py", line 578, in _create_connection
    transport, proto = yield from self._create_direct_connection(req)
  File "lib\aiohttp\connector.py", line 624, in _create_direct_connection
    (req.host, req.port, exc.strerror)) from exc
aiohttp.errors.ClientOSError: [Errno 1] Can not connect to wowtoken.info:443 [[SSL: CERTIFICATE_VERIFY_FAILED] certificate verify failed (_ssl.c:645)]

The above exception was the direct cause of the following exception:

Traceback (most recent call last):
  File "C:\Bot\Red-DiscordBot\cogs\blizzard.py", line 602, in print_token
    async with aiohttp.get(url, headers=self.header) as response:
  File "lib\aiohttp\client.py", line 565, in __aenter__
    self._resp = yield from self._coro
  File "lib\aiohttp\client.py", line 198, in _request
    conn = yield from self._connector.connect(req)
  File "lib\aiohttp\connector.py", line 314, in connect
    .format(key, exc.strerror)) from exc
aiohttp.errors.ClientOSError: [Errno 1] Cannot connect to host wowtoken.info:443 ssl:True [Can not connect to wowtoken.info:443 [[SSL: CERTIFICATE_VERIFY_FAILED] certificate verify failed (_ssl.c:645)]]

During handling of the above exception, another exception occurred:

Traceback (most recent call last):
  File "lib\discord\ext\commands\core.py", line 50, in wrapped
    ret = yield from coro(*args, **kwargs)
  File "C:\Bot\Red-DiscordBot\cogs\blizzard.py", line 391, in _token_warcraft
    await self.print_token(url, realm)
  File "C:\Bot\Red-DiscordBot\cogs\blizzard.py", line 620, in print_token
    await self.bot.say("Error finding WoW token prices.")
  File "lib\discord\ext\commands\bot.py", line 309, in _augmented_msg
    msg = yield from coro
  File "red.py", line 92, in send_message
    return await super().send_message(*args, **kwargs)
  File "lib\discord\client.py", line 1145, in send_message
    channel_id, guild_id = yield from self._resolve_destination(destination)
  File "lib\discord\client.py", line 289, in _resolve_destination
    raise InvalidArgument(fmt.format(destination))
discord.errors.InvalidArgument: Destination must be Channel, PrivateChannel, User, or Object. Received NoneType
[03/05/2017 04:45] ERROR red on_command_error 369: Exception in command 'warcraft token'
Traceback (most recent call last):
  File "lib\aiohttp\connector.py", line 601, in _create_direct_connection
    local_addr=self._local_addr)
  File "C:\Users\Administrator\AppData\Local\Programs\Python\Python35\lib\asyncio\base_events.py", line 713, in create_connection
    sock, protocol_factory, ssl, server_hostname)
  File "C:\Users\Administrator\AppData\Local\Programs\Python\Python35\lib\asyncio\base_events.py", line 736, in _create_connection_transport
    yield from waiter
  File "C:\Users\Administrator\AppData\Local\Programs\Python\Python35\lib\asyncio\futures.py", line 361, in __iter__
    yield self  # This tells Task to wait for completion.
  File "C:\Users\Administrator\AppData\Local\Programs\Python\Python35\lib\asyncio\tasks.py", line 296, in _wakeup
    future.result()
  File "C:\Users\Administrator\AppData\Local\Programs\Python\Python35\lib\asyncio\futures.py", line 274, in result
    raise self._exception
  File "C:\Users\Administrator\AppData\Local\Programs\Python\Python35\lib\asyncio\sslproto.py", line 492, in data_received
    ssldata, appdata = self._sslpipe.feed_ssldata(data)
  File "C:\Users\Administrator\AppData\Local\Programs\Python\Python35\lib\asyncio\sslproto.py", line 200, in feed_ssldata
    self._sslobj.do_handshake()
  File "C:\Users\Administrator\AppData\Local\Programs\Python\Python35\lib\ssl.py", line 633, in do_handshake
    self._sslobj.do_handshake()
ssl.SSLError: [SSL: CERTIFICATE_VERIFY_FAILED] certificate verify failed (_ssl.c:645)

The above exception was the direct cause of the following exception:

Traceback (most recent call last):
  File "lib\aiohttp\connector.py", line 304, in connect
    yield from self._create_connection(req)
  File "lib\aiohttp\connector.py", line 578, in _create_connection
    transport, proto = yield from self._create_direct_connection(req)
  File "lib\aiohttp\connector.py", line 624, in _create_direct_connection
    (req.host, req.port, exc.strerror)) from exc
aiohttp.errors.ClientOSError: [Errno 1] Can not connect to wowtoken.info:443 [[SSL: CERTIFICATE_VERIFY_FAILED] certificate verify failed (_ssl.c:645)]

The above exception was the direct cause of the following exception:

Traceback (most recent call last):
  File "C:\Bot\Red-DiscordBot\cogs\blizzard.py", line 602, in print_token
    async with aiohttp.get(url, headers=self.header) as response:
  File "lib\aiohttp\client.py", line 565, in __aenter__
    self._resp = yield from self._coro
  File "lib\aiohttp\client.py", line 198, in _request
    conn = yield from self._connector.connect(req)
  File "lib\aiohttp\connector.py", line 314, in connect
    .format(key, exc.strerror)) from exc
aiohttp.errors.ClientOSError: [Errno 1] Cannot connect to host wowtoken.info:443 ssl:True [Can not connect to wowtoken.info:443 [[SSL: CERTIFICATE_VERIFY_FAILED] certificate verify failed (_ssl.c:645)]]

During handling of the above exception, another exception occurred:

Traceback (most recent call last):
  File "lib\discord\ext\commands\core.py", line 50, in wrapped
    ret = yield from coro(*args, **kwargs)
  File "C:\Bot\Red-DiscordBot\cogs\blizzard.py", line 391, in _token_warcraft
    await self.print_token(url, realm)
  File "C:\Bot\Red-DiscordBot\cogs\blizzard.py", line 620, in print_token
    await self.bot.say("Error finding WoW token prices.")
  File "lib\discord\ext\commands\bot.py", line 309, in _augmented_msg
    msg = yield from coro
  File "red.py", line 92, in send_message
    return await super().send_message(*args, **kwargs)
  File "lib\discord\client.py", line 1145, in send_message
    channel_id, guild_id = yield from self._resolve_destination(destination)
  File "lib\discord\client.py", line 289, in _resolve_destination
    raise InvalidArgument(fmt.format(destination))
discord.errors.InvalidArgument: Destination must be Channel, PrivateChannel, User, or Object. Received NoneType
[03/05/2017 05:41] ERROR audio _join_voice_channel 647: 
Traceback (most recent call last):
  File "C:\Bot\Red-DiscordBot\cogs\audio.py", line 645, in _join_voice_channel
    timeout=5, loop=self.bot.loop)
  File "C:\Users\Administrator\AppData\Local\Programs\Python\Python35\lib\asyncio\tasks.py", line 396, in wait_for
    raise futures.TimeoutError()
concurrent.futures._base.TimeoutError
[03/05/2017 05:41] ERROR red on_command_error 369: Exception in command 'play'
Traceback (most recent call last):
  File "C:\Bot\Red-DiscordBot\cogs\audio.py", line 645, in _join_voice_channel
    timeout=5, loop=self.bot.loop)
  File "C:\Users\Administrator\AppData\Local\Programs\Python\Python35\lib\asyncio\tasks.py", line 396, in wait_for
    raise futures.TimeoutError()
concurrent.futures._base.TimeoutError

During handling of the above exception, another exception occurred:

Traceback (most recent call last):
  File "lib\discord\ext\commands\core.py", line 50, in wrapped
    ret = yield from coro(*args, **kwargs)
  File "C:\Bot\Red-DiscordBot\cogs\audio.py", line 1362, in play
    await self._join_voice_channel(voice_channel)
  File "C:\Bot\Red-DiscordBot\cogs\audio.py", line 649, in _join_voice_channel
    raise ConnectTimeout("We timed out connecting to a voice channel,"
cogs.audio.ConnectTimeout: We timed out connecting to a voice channel, please try again in 10 minutes.
[03/05/2017 05:41] ERROR red on_command_error 369: Exception in command 'play'
Traceback (most recent call last):
  File "lib\discord\ext\commands\core.py", line 50, in wrapped
    ret = yield from coro(*args, **kwargs)
  File "C:\Bot\Red-DiscordBot\cogs\audio.py", line 1362, in play
    await self._join_voice_channel(voice_channel)
  File "C:\Bot\Red-DiscordBot\cogs\audio.py", line 640, in _join_voice_channel
    " seconds.".format(diff))
cogs.audio.ConnectTimeout: You are on connect cooldown for another 294 seconds.
[03/05/2017 05:42] ERROR red on_command_error 369: Exception in command 'play'
Traceback (most recent call last):
  File "lib\discord\ext\commands\core.py", line 50, in wrapped
    ret = yield from coro(*args, **kwargs)
  File "C:\Bot\Red-DiscordBot\cogs\audio.py", line 1362, in play
    await self._join_voice_channel(voice_channel)
  File "C:\Bot\Red-DiscordBot\cogs\audio.py", line 640, in _join_voice_channel
    " seconds.".format(diff))
cogs.audio.ConnectTimeout: You are on connect cooldown for another 257 seconds.
[03/05/2017 05:42] ERROR red on_command_error 369: Exception in command 'play'
Traceback (most recent call last):
  File "lib\discord\ext\commands\core.py", line 50, in wrapped
    ret = yield from coro(*args, **kwargs)
  File "C:\Bot\Red-DiscordBot\cogs\audio.py", line 1362, in play
    await self._join_voice_channel(voice_channel)
  File "C:\Bot\Red-DiscordBot\cogs\audio.py", line 640, in _join_voice_channel
    " seconds.".format(diff))
cogs.audio.ConnectTimeout: You are on connect cooldown for another 235 seconds.
[03/05/2017 05:54] ERROR audio _join_voice_channel 647: 
Traceback (most recent call last):
  File "C:\Bot\Red-DiscordBot\cogs\audio.py", line 645, in _join_voice_channel
    timeout=5, loop=self.bot.loop)
  File "C:\Users\Administrator\AppData\Local\Programs\Python\Python35\lib\asyncio\tasks.py", line 396, in wait_for
    raise futures.TimeoutError()
concurrent.futures._base.TimeoutError
[03/05/2017 05:54] ERROR red on_command_error 369: Exception in command 'play'
Traceback (most recent call last):
  File "C:\Bot\Red-DiscordBot\cogs\audio.py", line 645, in _join_voice_channel
    timeout=5, loop=self.bot.loop)
  File "C:\Users\Administrator\AppData\Local\Programs\Python\Python35\lib\asyncio\tasks.py", line 396, in wait_for
    raise futures.TimeoutError()
concurrent.futures._base.TimeoutError

During handling of the above exception, another exception occurred:

Traceback (most recent call last):
  File "lib\discord\ext\commands\core.py", line 50, in wrapped
    ret = yield from coro(*args, **kwargs)
  File "C:\Bot\Red-DiscordBot\cogs\audio.py", line 1362, in play
    await self._join_voice_channel(voice_channel)
  File "C:\Bot\Red-DiscordBot\cogs\audio.py", line 649, in _join_voice_channel
    raise ConnectTimeout("We timed out connecting to a voice channel,"
cogs.audio.ConnectTimeout: We timed out connecting to a voice channel, please try again in 10 minutes.
[03/05/2017 05:54] ERROR red on_command_error 369: Exception in command 'play'
Traceback (most recent call last):
  File "lib\discord\ext\commands\core.py", line 50, in wrapped
    ret = yield from coro(*args, **kwargs)
  File "C:\Bot\Red-DiscordBot\cogs\audio.py", line 1362, in play
    await self._join_voice_channel(voice_channel)
  File "C:\Bot\Red-DiscordBot\cogs\audio.py", line 640, in _join_voice_channel
    " seconds.".format(diff))
cogs.audio.ConnectTimeout: You are on connect cooldown for another 288 seconds.
[03/05/2017 05:55] ERROR red on_command_error 369: Exception in command 'play'
Traceback (most recent call last):
  File "lib\discord\ext\commands\core.py", line 50, in wrapped
    ret = yield from coro(*args, **kwargs)
  File "C:\Bot\Red-DiscordBot\cogs\audio.py", line 1362, in play
    await self._join_voice_channel(voice_channel)
  File "C:\Bot\Red-DiscordBot\cogs\audio.py", line 640, in _join_voice_channel
    " seconds.".format(diff))
cogs.audio.ConnectTimeout: You are on connect cooldown for another 256 seconds.
[03/05/2017 05:55] ERROR red on_command_error 369: Exception in command 'play'
Traceback (most recent call last):
  File "lib\discord\ext\commands\core.py", line 50, in wrapped
    ret = yield from coro(*args, **kwargs)
  File "C:\Bot\Red-DiscordBot\cogs\audio.py", line 1362, in play
    await self._join_voice_channel(voice_channel)
  File "C:\Bot\Red-DiscordBot\cogs\audio.py", line 640, in _join_voice_channel
    " seconds.".format(diff))
cogs.audio.ConnectTimeout: You are on connect cooldown for another 236 seconds.
[03/05/2017 05:55] ERROR red on_command_error 369: Exception in command 'play'
Traceback (most recent call last):
  File "lib\discord\ext\commands\core.py", line 50, in wrapped
    ret = yield from coro(*args, **kwargs)
  File "C:\Bot\Red-DiscordBot\cogs\audio.py", line 1362, in play
    await self._join_voice_channel(voice_channel)
  File "C:\Bot\Red-DiscordBot\cogs\audio.py", line 640, in _join_voice_channel
    " seconds.".format(diff))
cogs.audio.ConnectTimeout: You are on connect cooldown for another 223 seconds.
[03/05/2017 05:56] ERROR red on_command_error 369: Exception in command 'play'
Traceback (most recent call last):
  File "lib\discord\ext\commands\core.py", line 50, in wrapped
    ret = yield from coro(*args, **kwargs)
  File "C:\Bot\Red-DiscordBot\cogs\audio.py", line 1362, in play
    await self._join_voice_channel(voice_channel)
  File "C:\Bot\Red-DiscordBot\cogs\audio.py", line 640, in _join_voice_channel
    " seconds.".format(diff))
cogs.audio.ConnectTimeout: You are on connect cooldown for another 207 seconds.
[03/05/2017 07:28] ERROR audio _join_voice_channel 647: 
Traceback (most recent call last):
  File "C:\Bot\Red-DiscordBot\cogs\audio.py", line 645, in _join_voice_channel
    timeout=5, loop=self.bot.loop)
  File "C:\Users\Administrator\AppData\Local\Programs\Python\Python35\lib\asyncio\tasks.py", line 396, in wait_for
    raise futures.TimeoutError()
concurrent.futures._base.TimeoutError
[03/05/2017 07:28] ERROR red on_command_error 369: Exception in command 'play'
Traceback (most recent call last):
  File "C:\Bot\Red-DiscordBot\cogs\audio.py", line 645, in _join_voice_channel
    timeout=5, loop=self.bot.loop)
  File "C:\Users\Administrator\AppData\Local\Programs\Python\Python35\lib\asyncio\tasks.py", line 396, in wait_for
    raise futures.TimeoutError()
concurrent.futures._base.TimeoutError

During handling of the above exception, another exception occurred:

Traceback (most recent call last):
  File "lib\discord\ext\commands\core.py", line 50, in wrapped
    ret = yield from coro(*args, **kwargs)
  File "C:\Bot\Red-DiscordBot\cogs\audio.py", line 1362, in play
    await self._join_voice_channel(voice_channel)
  File "C:\Bot\Red-DiscordBot\cogs\audio.py", line 649, in _join_voice_channel
    raise ConnectTimeout("We timed out connecting to a voice channel,"
cogs.audio.ConnectTimeout: We timed out connecting to a voice channel, please try again in 10 minutes.
[03/05/2017 07:31] ERROR red on_command_error 369: Exception in command 'yt'
Traceback (most recent call last):
  File "lib\discord\ext\commands\core.py", line 50, in wrapped
    ret = yield from coro(*args, **kwargs)
  File "C:\Bot\Red-DiscordBot\cogs\audio.py", line 1908, in yt_search
    await ctx.invoke(self.play, url_or_search_terms=search_terms)
  File "lib\discord\ext\commands\context.py", line 112, in invoke
    ret = yield from command.callback(*arguments, **kwargs)
  File "C:\Bot\Red-DiscordBot\cogs\audio.py", line 1362, in play
    await self._join_voice_channel(voice_channel)
  File "C:\Bot\Red-DiscordBot\cogs\audio.py", line 640, in _join_voice_channel
    " seconds.".format(diff))
cogs.audio.ConnectTimeout: You are on connect cooldown for another 110 seconds.
[03/05/2017 07:34] ERROR audio _join_voice_channel 647: 
Traceback (most recent call last):
  File "C:\Bot\Red-DiscordBot\cogs\audio.py", line 645, in _join_voice_channel
    timeout=5, loop=self.bot.loop)
  File "C:\Users\Administrator\AppData\Local\Programs\Python\Python35\lib\asyncio\tasks.py", line 396, in wait_for
    raise futures.TimeoutError()
concurrent.futures._base.TimeoutError
[03/05/2017 07:34] ERROR red on_command_error 369: Exception in command 'sing'
Traceback (most recent call last):
  File "C:\Bot\Red-DiscordBot\cogs\audio.py", line 645, in _join_voice_channel
    timeout=5, loop=self.bot.loop)
  File "C:\Users\Administrator\AppData\Local\Programs\Python\Python35\lib\asyncio\tasks.py", line 396, in wait_for
    raise futures.TimeoutError()
concurrent.futures._base.TimeoutError

During handling of the above exception, another exception occurred:

Traceback (most recent call last):
  File "lib\discord\ext\commands\core.py", line 50, in wrapped
    ret = yield from coro(*args, **kwargs)
  File "C:\Bot\Red-DiscordBot\cogs\audio.py", line 1848, in sing
    await ctx.invoke(self.play, url_or_search_terms=url)
  File "lib\discord\ext\commands\context.py", line 112, in invoke
    ret = yield from command.callback(*arguments, **kwargs)
  File "C:\Bot\Red-DiscordBot\cogs\audio.py", line 1362, in play
    await self._join_voice_channel(voice_channel)
  File "C:\Bot\Red-DiscordBot\cogs\audio.py", line 649, in _join_voice_channel
    raise ConnectTimeout("We timed out connecting to a voice channel,"
cogs.audio.ConnectTimeout: We timed out connecting to a voice channel, please try again in 10 minutes.
[03/05/2017 09:40] ERROR audio _join_voice_channel 647: 
Traceback (most recent call last):
  File "C:\Bot\Red-DiscordBot\cogs\audio.py", line 645, in _join_voice_channel
    timeout=5, loop=self.bot.loop)
  File "C:\Users\Administrator\AppData\Local\Programs\Python\Python35\lib\asyncio\tasks.py", line 396, in wait_for
    raise futures.TimeoutError()
concurrent.futures._base.TimeoutError
[03/05/2017 09:40] ERROR red on_command_error 369: Exception in command 'play'
Traceback (most recent call last):
  File "C:\Bot\Red-DiscordBot\cogs\audio.py", line 645, in _join_voice_channel
    timeout=5, loop=self.bot.loop)
  File "C:\Users\Administrator\AppData\Local\Programs\Python\Python35\lib\asyncio\tasks.py", line 396, in wait_for
    raise futures.TimeoutError()
concurrent.futures._base.TimeoutError

During handling of the above exception, another exception occurred:

Traceback (most recent call last):
  File "lib\discord\ext\commands\core.py", line 50, in wrapped
    ret = yield from coro(*args, **kwargs)
  File "C:\Bot\Red-DiscordBot\cogs\audio.py", line 1362, in play
    await self._join_voice_channel(voice_channel)
  File "C:\Bot\Red-DiscordBot\cogs\audio.py", line 649, in _join_voice_channel
    raise ConnectTimeout("We timed out connecting to a voice channel,"
cogs.audio.ConnectTimeout: We timed out connecting to a voice channel, please try again in 10 minutes.
[04/05/2017 00:47] WARNING audio _play 814: I can't play URL below because it is too long. Use [p]audioset maxlength to change this.

[SEARCH:]逗鱼时刻2016
[04/05/2017 00:54] WARNING audio _play 814: I can't play URL below because it is too long. Use [p]audioset maxlength to change this.

[SEARCH:]逗鱼时刻2016
[04/05/2017 05:25] ERROR red on_command_error 369: Exception in command 'play'
Traceback (most recent call last):
  File "lib\discord\ext\commands\core.py", line 50, in wrapped
    ret = yield from coro(*args, **kwargs)
  File "C:\Bot\Red-DiscordBot\cogs\audio.py", line 1338, in play
    await ctx.invoke(self._queue, url=url)
  File "lib\discord\ext\commands\context.py", line 112, in invoke
    ret = yield from command.callback(*arguments, **kwargs)
  File "C:\Bot\Red-DiscordBot\cogs\audio.py", line 1665, in _queue
    await self.bot.say("Queued.")
  File "lib\discord\ext\commands\bot.py", line 309, in _augmented_msg
    msg = yield from coro
  File "red.py", line 92, in send_message
    return await super().send_message(*args, **kwargs)
  File "lib\discord\client.py", line 1152, in send_message
    data = yield from self.http.send_message(channel_id, content, guild_id=guild_id, tts=tts, embed=embed)
  File "lib\discord\http.py", line 196, in request
    raise Forbidden(r, data)
discord.errors.Forbidden: FORBIDDEN (status code: 403): Missing Permissions
[04/05/2017 06:06] WARNING audio _play 814: I can't play URL below because it is too long. Use [p]audioset maxlength to change this.

[SEARCH:]开宗恋爱教学
[04/05/2017 17:33] WARNING audio _play 814: I can't play URL below because it is too long. Use [p]audioset maxlength to change this.

[SEARCH:]zvezda
[04/05/2017 17:33] WARNING audio _play 814: I can't play URL below because it is too long. Use [p]audioset maxlength to change this.

[SEARCH:]zvezda
[04/05/2017 18:45] ERROR red on_command_error 369: Exception in command 'penis'
Traceback (most recent call last):
  File "lib\discord\ext\commands\core.py", line 50, in wrapped
    ret = yield from coro(*args, **kwargs)
  File "C:\Bot\Red-DiscordBot\cogs\penis.py", line 20, in penis
    await self.bot.say("Size: " + dong)
  File "lib\discord\ext\commands\bot.py", line 309, in _augmented_msg
    msg = yield from coro
  File "red.py", line 92, in send_message
    return await super().send_message(*args, **kwargs)
  File "lib\discord\client.py", line 1152, in send_message
    data = yield from self.http.send_message(channel_id, content, guild_id=guild_id, tts=tts, embed=embed)
  File "lib\discord\http.py", line 196, in request
    raise Forbidden(r, data)
discord.errors.Forbidden: FORBIDDEN (status code: 403): Missing Permissions
[04/05/2017 18:46] ERROR red on_command_error 369: Exception in command 'skip'
Traceback (most recent call last):
  File "lib\discord\ext\commands\core.py", line 50, in wrapped
    ret = yield from coro(*args, **kwargs)
  File "C:\Bot\Red-DiscordBot\cogs\audio.py", line 1820, in skip
    await self.bot.say("Can't skip if I'm not playing.")
  File "lib\discord\ext\commands\bot.py", line 309, in _augmented_msg
    msg = yield from coro
  File "red.py", line 92, in send_message
    return await super().send_message(*args, **kwargs)
  File "lib\discord\client.py", line 1152, in send_message
    data = yield from self.http.send_message(channel_id, content, guild_id=guild_id, tts=tts, embed=embed)
  File "lib\discord\http.py", line 196, in request
    raise Forbidden(r, data)
discord.errors.Forbidden: FORBIDDEN (status code: 403): Missing Permissions
[05/05/2017 00:29] ERROR red on_command_error 369: Exception in command 'penis'
Traceback (most recent call last):
  File "lib\discord\ext\commands\core.py", line 50, in wrapped
    ret = yield from coro(*args, **kwargs)
  File "C:\Bot\Red-DiscordBot\cogs\penis.py", line 20, in penis
    await self.bot.say("Size: " + dong)
  File "lib\discord\ext\commands\bot.py", line 309, in _augmented_msg
    msg = yield from coro
  File "red.py", line 92, in send_message
    return await super().send_message(*args, **kwargs)
  File "lib\discord\client.py", line 1152, in send_message
    data = yield from self.http.send_message(channel_id, content, guild_id=guild_id, tts=tts, embed=embed)
  File "lib\discord\http.py", line 196, in request
    raise Forbidden(r, data)
discord.errors.Forbidden: FORBIDDEN (status code: 403): Missing Permissions
[05/05/2017 03:10] ERROR red on_command_error 369: Exception in command 'audioset volume'
Traceback (most recent call last):
  File "lib\discord\ext\commands\core.py", line 50, in wrapped
    ret = yield from coro(*args, **kwargs)
  File "C:\Bot\Red-DiscordBot\cogs\audio.py", line 1141, in audioset_volume
    await self.bot.say(msg)
  File "lib\discord\ext\commands\bot.py", line 309, in _augmented_msg
    msg = yield from coro
  File "red.py", line 92, in send_message
    return await super().send_message(*args, **kwargs)
  File "lib\discord\client.py", line 1152, in send_message
    data = yield from self.http.send_message(channel_id, content, guild_id=guild_id, tts=tts, embed=embed)
  File "lib\discord\http.py", line 196, in request
    raise Forbidden(r, data)
discord.errors.Forbidden: FORBIDDEN (status code: 403): Missing Permissions
[06/05/2017 00:09] ERROR red on_command_error 369: Exception in command 'penis'
Traceback (most recent call last):
  File "lib\discord\ext\commands\core.py", line 50, in wrapped
    ret = yield from coro(*args, **kwargs)
  File "C:\Bot\Red-DiscordBot\cogs\penis.py", line 20, in penis
    await self.bot.say("Size: " + dong)
  File "lib\discord\ext\commands\bot.py", line 309, in _augmented_msg
    msg = yield from coro
  File "red.py", line 92, in send_message
    return await super().send_message(*args, **kwargs)
  File "lib\discord\client.py", line 1152, in send_message
    data = yield from self.http.send_message(channel_id, content, guild_id=guild_id, tts=tts, embed=embed)
  File "lib\discord\http.py", line 196, in request
    raise Forbidden(r, data)
discord.errors.Forbidden: FORBIDDEN (status code: 403): Missing Permissions
[06/05/2017 00:45] ERROR red load_cogs 573: ('invalid syntax', ('C:\\Bot\\Red-DiscordBot\\cogs\\greet.py', 15, 15, '        if rng) == 0\n'))
Traceback (most recent call last):
  File "C:\Bot\Red-DiscordBot\cogs\owner.py", line 945, in _load_cog
    mod_obj = importlib.import_module(cogname)
  File "C:\Users\Administrator\AppData\Local\Programs\Python\Python35\lib\importlib\__init__.py", line 126, in import_module
    return _bootstrap._gcd_import(name[level:], package, level)
  File "<frozen importlib._bootstrap>", line 986, in _gcd_import
  File "<frozen importlib._bootstrap>", line 969, in _find_and_load
  File "<frozen importlib._bootstrap>", line 958, in _find_and_load_unlocked
  File "<frozen importlib._bootstrap>", line 673, in _load_unlocked
  File "<frozen importlib._bootstrap_external>", line 661, in exec_module
  File "<frozen importlib._bootstrap_external>", line 767, in get_code
  File "<frozen importlib._bootstrap_external>", line 727, in source_to_code
  File "<frozen importlib._bootstrap>", line 222, in _call_with_frames_removed
  File "C:\Bot\Red-DiscordBot\cogs\greet.py", line 15
    if rng) == 0
          ^
SyntaxError: invalid syntax

During handling of the above exception, another exception occurred:

Traceback (most recent call last):
  File "red.py", line 570, in load_cogs
    owner_cog._load_cog(extension)
  File "C:\Bot\Red-DiscordBot\cogs\owner.py", line 949, in _load_cog
    raise CogLoadError(*e.args)
cogs.owner.CogLoadError: ('invalid syntax', ('C:\\Bot\\Red-DiscordBot\\cogs\\greet.py', 15, 15, '        if rng) == 0\n'))
[06/05/2017 01:19] ERROR red on_command_error 369: Exception in command 'penis'
Traceback (most recent call last):
  File "lib\discord\ext\commands\core.py", line 50, in wrapped
    ret = yield from coro(*args, **kwargs)
  File "C:\Bot\Red-DiscordBot\cogs\penis.py", line 20, in penis
    await self.bot.say("Size: " + dong)
  File "lib\discord\ext\commands\bot.py", line 309, in _augmented_msg
    msg = yield from coro
  File "red.py", line 92, in send_message
    return await super().send_message(*args, **kwargs)
  File "lib\discord\client.py", line 1152, in send_message
    data = yield from self.http.send_message(channel_id, content, guild_id=guild_id, tts=tts, embed=embed)
  File "lib\discord\http.py", line 196, in request
    raise Forbidden(r, data)
discord.errors.Forbidden: FORBIDDEN (status code: 403): Missing Permissions
[06/05/2017 02:04] ERROR red on_command_error 369: Exception in command 'greet'
Traceback (most recent call last):
  File "lib\discord\ext\commands\core.py", line 50, in wrapped
    ret = yield from coro(*args, **kwargs)
  File "C:\Bot\Red-DiscordBot\cogs\greet.py", line 14, in greet
    await self.bot.say("http://imgur.com/47vI9T5")
  File "lib\discord\ext\commands\bot.py", line 309, in _augmented_msg
    msg = yield from coro
  File "red.py", line 92, in send_message
    return await super().send_message(*args, **kwargs)
  File "lib\discord\client.py", line 1152, in send_message
    data = yield from self.http.send_message(channel_id, content, guild_id=guild_id, tts=tts, embed=embed)
  File "lib\discord\http.py", line 196, in request
    raise Forbidden(r, data)
discord.errors.Forbidden: FORBIDDEN (status code: 403): Missing Permissions
[06/05/2017 05:30] ERROR red load_cogs 573: ('named arguments must follow bare *', ('C:\\Bot\\Red-DiscordBot\\cogs\\greet.py', 12, 26, 'async def greet(self, *):\n'))
Traceback (most recent call last):
  File "C:\Bot\Red-DiscordBot\cogs\owner.py", line 945, in _load_cog
    mod_obj = importlib.import_module(cogname)
  File "C:\Users\Administrator\AppData\Local\Programs\Python\Python35\lib\importlib\__init__.py", line 126, in import_module
    return _bootstrap._gcd_import(name[level:], package, level)
  File "<frozen importlib._bootstrap>", line 986, in _gcd_import
  File "<frozen importlib._bootstrap>", line 969, in _find_and_load
  File "<frozen importlib._bootstrap>", line 958, in _find_and_load_unlocked
  File "<frozen importlib._bootstrap>", line 673, in _load_unlocked
  File "<frozen importlib._bootstrap_external>", line 661, in exec_module
  File "<frozen importlib._bootstrap_external>", line 767, in get_code
  File "<frozen importlib._bootstrap_external>", line 727, in source_to_code
  File "<frozen importlib._bootstrap>", line 222, in _call_with_frames_removed
  File "C:\Bot\Red-DiscordBot\cogs\greet.py", line 12
    async def greet(self, *):
                            ^
SyntaxError: named arguments must follow bare *

During handling of the above exception, another exception occurred:

Traceback (most recent call last):
  File "red.py", line 570, in load_cogs
    owner_cog._load_cog(extension)
  File "C:\Bot\Red-DiscordBot\cogs\owner.py", line 949, in _load_cog
    raise CogLoadError(*e.args)
cogs.owner.CogLoadError: ('named arguments must follow bare *', ('C:\\Bot\\Red-DiscordBot\\cogs\\greet.py', 12, 26, 'async def greet(self, *):\n'))
[06/05/2017 06:11] ERROR red on_command_error 369: Exception in command 'set'
Traceback (most recent call last):
  File "lib\discord\ext\commands\core.py", line 50, in wrapped
    ret = yield from coro(*args, **kwargs)
  File "C:\Bot\Red-DiscordBot\cogs\owner.py", line 260, in _set
    await self.bot.send_cmd_help(ctx)
  File "red.py", line 141, in send_cmd_help
    await self.send_message(ctx.message.channel, page)
  File "red.py", line 92, in send_message
    return await super().send_message(*args, **kwargs)
  File "lib\discord\client.py", line 1152, in send_message
    data = yield from self.http.send_message(channel_id, content, guild_id=guild_id, tts=tts, embed=embed)
  File "lib\discord\http.py", line 196, in request
    raise Forbidden(r, data)
discord.errors.Forbidden: FORBIDDEN (status code: 403): Missing Permissions
[06/05/2017 06:48] ERROR owner load 68: ('named arguments must follow bare *', ('C:\\Bot\\Red-DiscordBot\\cogs\\greet.py', 12, 26, 'async def greet(self, *):\n'))
Traceback (most recent call last):
  File "C:\Bot\Red-DiscordBot\cogs\owner.py", line 945, in _load_cog
    mod_obj = importlib.import_module(cogname)
  File "C:\Users\Administrator\AppData\Local\Programs\Python\Python35\lib\importlib\__init__.py", line 126, in import_module
    return _bootstrap._gcd_import(name[level:], package, level)
  File "<frozen importlib._bootstrap>", line 986, in _gcd_import
  File "<frozen importlib._bootstrap>", line 969, in _find_and_load
  File "<frozen importlib._bootstrap>", line 958, in _find_and_load_unlocked
  File "<frozen importlib._bootstrap>", line 673, in _load_unlocked
  File "<frozen importlib._bootstrap_external>", line 661, in exec_module
  File "<frozen importlib._bootstrap_external>", line 767, in get_code
  File "<frozen importlib._bootstrap_external>", line 727, in source_to_code
  File "<frozen importlib._bootstrap>", line 222, in _call_with_frames_removed
  File "C:\Bot\Red-DiscordBot\cogs\greet.py", line 12
    async def greet(self, *):
                            ^
SyntaxError: named arguments must follow bare *

During handling of the above exception, another exception occurred:

Traceback (most recent call last):
  File "C:\Bot\Red-DiscordBot\cogs\owner.py", line 64, in load
    self._load_cog(module)
  File "C:\Bot\Red-DiscordBot\cogs\owner.py", line 949, in _load_cog
    raise CogLoadError(*e.args)
cogs.owner.CogLoadError: ('named arguments must follow bare *', ('C:\\Bot\\Red-DiscordBot\\cogs\\greet.py', 12, 26, 'async def greet(self, *):\n'))
[06/05/2017 06:50] ERROR owner load 68: ('named arguments must follow bare *', ('C:\\Bot\\Red-DiscordBot\\cogs\\greet.py', 12, 26, 'async def greet(self, *):\n'))
Traceback (most recent call last):
  File "C:\Bot\Red-DiscordBot\cogs\owner.py", line 945, in _load_cog
    mod_obj = importlib.import_module(cogname)
  File "C:\Users\Administrator\AppData\Local\Programs\Python\Python35\lib\importlib\__init__.py", line 126, in import_module
    return _bootstrap._gcd_import(name[level:], package, level)
  File "<frozen importlib._bootstrap>", line 986, in _gcd_import
  File "<frozen importlib._bootstrap>", line 969, in _find_and_load
  File "<frozen importlib._bootstrap>", line 958, in _find_and_load_unlocked
  File "<frozen importlib._bootstrap>", line 673, in _load_unlocked
  File "<frozen importlib._bootstrap_external>", line 661, in exec_module
  File "<frozen importlib._bootstrap_external>", line 767, in get_code
  File "<frozen importlib._bootstrap_external>", line 727, in source_to_code
  File "<frozen importlib._bootstrap>", line 222, in _call_with_frames_removed
  File "C:\Bot\Red-DiscordBot\cogs\greet.py", line 12
    async def greet(self, *):
                            ^
SyntaxError: named arguments must follow bare *

During handling of the above exception, another exception occurred:

Traceback (most recent call last):
  File "C:\Bot\Red-DiscordBot\cogs\owner.py", line 64, in load
    self._load_cog(module)
  File "C:\Bot\Red-DiscordBot\cogs\owner.py", line 949, in _load_cog
    raise CogLoadError(*e.args)
cogs.owner.CogLoadError: ('named arguments must follow bare *', ('C:\\Bot\\Red-DiscordBot\\cogs\\greet.py', 12, 26, 'async def greet(self, *):\n'))
[06/05/2017 07:07] ERROR owner load 73: Command penis is already registered.
Traceback (most recent call last):
  File "C:\Bot\Red-DiscordBot\cogs\owner.py", line 64, in load
    self._load_cog(module)
  File "C:\Bot\Red-DiscordBot\cogs\owner.py", line 947, in _load_cog
    self.bot.load_extension(mod_obj.__name__)
  File "lib\discord\ext\commands\bot.py", line 738, in load_extension
    lib.setup(self)
  File "C:\Bot\Red-DiscordBot\cogs\vagina.py", line 24, in setup
    bot.add_cog(Vagina(bot))
  File "lib\discord\ext\commands\bot.py", line 655, in add_cog
    self.add_command(member)
  File "lib\discord\ext\commands\core.py", line 487, in add_command
    raise discord.ClientException('Command {0.name} is already registered.'.format(command))
discord.errors.ClientException: Command penis is already registered.
[06/05/2017 22:59] ERROR owner load 68: ('invalid syntax', ('C:\\Bot\\Red-DiscordBot\\cogs\\greet.py', 15, 31, '            if message.author = "Dragon":\n'))
Traceback (most recent call last):
  File "C:\Bot\Red-DiscordBot\cogs\owner.py", line 945, in _load_cog
    mod_obj = importlib.import_module(cogname)
  File "C:\Users\Administrator\AppData\Local\Programs\Python\Python35\lib\importlib\__init__.py", line 126, in import_module
    return _bootstrap._gcd_import(name[level:], package, level)
  File "<frozen importlib._bootstrap>", line 986, in _gcd_import
  File "<frozen importlib._bootstrap>", line 969, in _find_and_load
  File "<frozen importlib._bootstrap>", line 958, in _find_and_load_unlocked
  File "<frozen importlib._bootstrap>", line 673, in _load_unlocked
  File "<frozen importlib._bootstrap_external>", line 661, in exec_module
  File "<frozen importlib._bootstrap_external>", line 767, in get_code
  File "<frozen importlib._bootstrap_external>", line 727, in source_to_code
  File "<frozen importlib._bootstrap>", line 222, in _call_with_frames_removed
  File "C:\Bot\Red-DiscordBot\cogs\greet.py", line 15
    if message.author = "Dragon":
                      ^
SyntaxError: invalid syntax

During handling of the above exception, another exception occurred:

Traceback (most recent call last):
  File "C:\Bot\Red-DiscordBot\cogs\owner.py", line 64, in load
    self._load_cog(module)
  File "C:\Bot\Red-DiscordBot\cogs\owner.py", line 949, in _load_cog
    raise CogLoadError(*e.args)
cogs.owner.CogLoadError: ('invalid syntax', ('C:\\Bot\\Red-DiscordBot\\cogs\\greet.py', 15, 31, '            if message.author = "Dragon":\n'))
[06/05/2017 23:00] ERROR owner load 68: ('invalid syntax', ('C:\\Bot\\Red-DiscordBot\\cogs\\greet.py', 15, 31, '            if message.author = "Dragon":\n'))
Traceback (most recent call last):
  File "C:\Bot\Red-DiscordBot\cogs\owner.py", line 945, in _load_cog
    mod_obj = importlib.import_module(cogname)
  File "C:\Users\Administrator\AppData\Local\Programs\Python\Python35\lib\importlib\__init__.py", line 126, in import_module
    return _bootstrap._gcd_import(name[level:], package, level)
  File "<frozen importlib._bootstrap>", line 986, in _gcd_import
  File "<frozen importlib._bootstrap>", line 969, in _find_and_load
  File "<frozen importlib._bootstrap>", line 958, in _find_and_load_unlocked
  File "<frozen importlib._bootstrap>", line 673, in _load_unlocked
  File "<frozen importlib._bootstrap_external>", line 661, in exec_module
  File "<frozen importlib._bootstrap_external>", line 767, in get_code
  File "<frozen importlib._bootstrap_external>", line 727, in source_to_code
  File "<frozen importlib._bootstrap>", line 222, in _call_with_frames_removed
  File "C:\Bot\Red-DiscordBot\cogs\greet.py", line 15
    if message.author = "Dragon":
                      ^
SyntaxError: invalid syntax

During handling of the above exception, another exception occurred:

Traceback (most recent call last):
  File "C:\Bot\Red-DiscordBot\cogs\owner.py", line 64, in load
    self._load_cog(module)
  File "C:\Bot\Red-DiscordBot\cogs\owner.py", line 949, in _load_cog
    raise CogLoadError(*e.args)
cogs.owner.CogLoadError: ('invalid syntax', ('C:\\Bot\\Red-DiscordBot\\cogs\\greet.py', 15, 31, '            if message.author = "Dragon":\n'))
[06/05/2017 23:31] ERROR owner load 68: ('invalid syntax', ('C:\\Bot\\Red-DiscordBot\\cogs\\greet.py', 18, 31, '            if message.author = "Dragon#1189":\n'))
Traceback (most recent call last):
  File "C:\Bot\Red-DiscordBot\cogs\owner.py", line 945, in _load_cog
    mod_obj = importlib.import_module(cogname)
  File "C:\Users\Administrator\AppData\Local\Programs\Python\Python35\lib\importlib\__init__.py", line 126, in import_module
    return _bootstrap._gcd_import(name[level:], package, level)
  File "<frozen importlib._bootstrap>", line 986, in _gcd_import
  File "<frozen importlib._bootstrap>", line 969, in _find_and_load
  File "<frozen importlib._bootstrap>", line 958, in _find_and_load_unlocked
  File "<frozen importlib._bootstrap>", line 673, in _load_unlocked
  File "<frozen importlib._bootstrap_external>", line 661, in exec_module
  File "<frozen importlib._bootstrap_external>", line 767, in get_code
  File "<frozen importlib._bootstrap_external>", line 727, in source_to_code
  File "<frozen importlib._bootstrap>", line 222, in _call_with_frames_removed
  File "C:\Bot\Red-DiscordBot\cogs\greet.py", line 18
    if message.author = "Dragon#1189":
                      ^
SyntaxError: invalid syntax

During handling of the above exception, another exception occurred:

Traceback (most recent call last):
  File "C:\Bot\Red-DiscordBot\cogs\owner.py", line 64, in load
    self._load_cog(module)
  File "C:\Bot\Red-DiscordBot\cogs\owner.py", line 949, in _load_cog
    raise CogLoadError(*e.args)
cogs.owner.CogLoadError: ('invalid syntax', ('C:\\Bot\\Red-DiscordBot\\cogs\\greet.py', 18, 31, '            if message.author = "Dragon#1189":\n'))
[07/05/2017 19:26] ERROR red on_command_error 369: Exception in command 'load'
Traceback (most recent call last):
  File "lib\discord\ext\commands\core.py", line 50, in wrapped
    ret = yield from coro(*args, **kwargs)
  File "C:\Bot\Red-DiscordBot\cogs\owner.py", line 81, in load
    await self.bot.say("The cog has been loaded.")
  File "lib\discord\ext\commands\bot.py", line 309, in _augmented_msg
    msg = yield from coro
  File "red.py", line 92, in send_message
    return await super().send_message(*args, **kwargs)
  File "lib\discord\client.py", line 1152, in send_message
    data = yield from self.http.send_message(channel_id, content, guild_id=guild_id, tts=tts, embed=embed)
  File "lib\discord\http.py", line 196, in request
    raise Forbidden(r, data)
discord.errors.Forbidden: FORBIDDEN (status code: 403): Missing Permissions
[08/05/2017 00:20] ERROR red on_command_error 369: Exception in command 'play'
Traceback (most recent call last):
  File "lib\discord\ext\commands\core.py", line 50, in wrapped
    ret = yield from coro(*args, **kwargs)
  File "C:\Bot\Red-DiscordBot\cogs\audio.py", line 1338, in play
    await ctx.invoke(self._queue, url=url)
  File "lib\discord\ext\commands\context.py", line 112, in invoke
    ret = yield from command.callback(*arguments, **kwargs)
  File "C:\Bot\Red-DiscordBot\cogs\audio.py", line 1665, in _queue
    await self.bot.say("Queued.")
  File "lib\discord\ext\commands\bot.py", line 309, in _augmented_msg
    msg = yield from coro
  File "red.py", line 92, in send_message
    return await super().send_message(*args, **kwargs)
  File "lib\discord\client.py", line 1152, in send_message
    data = yield from self.http.send_message(channel_id, content, guild_id=guild_id, tts=tts, embed=embed)
  File "lib\discord\http.py", line 196, in request
    raise Forbidden(r, data)
discord.errors.Forbidden: FORBIDDEN (status code: 403): Missing Permissions
[08/05/2017 00:20] ERROR red on_command_error 369: Exception in command 'skip'
Traceback (most recent call last):
  File "lib\discord\ext\commands\core.py", line 50, in wrapped
    ret = yield from coro(*args, **kwargs)
  File "C:\Bot\Red-DiscordBot\cogs\audio.py", line 1816, in skip
    await self.bot.reply(reply)
  File "lib\discord\ext\commands\bot.py", line 309, in _augmented_msg
    msg = yield from coro
  File "red.py", line 92, in send_message
    return await super().send_message(*args, **kwargs)
  File "lib\discord\client.py", line 1152, in send_message
    data = yield from self.http.send_message(channel_id, content, guild_id=guild_id, tts=tts, embed=embed)
  File "lib\discord\http.py", line 196, in request
    raise Forbidden(r, data)
discord.errors.Forbidden: FORBIDDEN (status code: 403): Missing Permissions
[08/05/2017 00:20] ERROR red on_command_error 369: Exception in command 'skip'
Traceback (most recent call last):
  File "lib\discord\ext\commands\core.py", line 50, in wrapped
    ret = yield from coro(*args, **kwargs)
  File "C:\Bot\Red-DiscordBot\cogs\audio.py", line 1816, in skip
    await self.bot.reply(reply)
  File "lib\discord\ext\commands\bot.py", line 309, in _augmented_msg
    msg = yield from coro
  File "red.py", line 92, in send_message
    return await super().send_message(*args, **kwargs)
  File "lib\discord\client.py", line 1152, in send_message
    data = yield from self.http.send_message(channel_id, content, guild_id=guild_id, tts=tts, embed=embed)
  File "lib\discord\http.py", line 196, in request
    raise Forbidden(r, data)
discord.errors.Forbidden: FORBIDDEN (status code: 403): Missing Permissions
[08/05/2017 00:24] ERROR red on_command_error 369: Exception in command 'skip'
Traceback (most recent call last):
  File "lib\discord\ext\commands\core.py", line 50, in wrapped
    ret = yield from coro(*args, **kwargs)
  File "C:\Bot\Red-DiscordBot\cogs\audio.py", line 1816, in skip
    await self.bot.reply(reply)
  File "lib\discord\ext\commands\bot.py", line 309, in _augmented_msg
    msg = yield from coro
  File "red.py", line 92, in send_message
    return await super().send_message(*args, **kwargs)
  File "lib\discord\client.py", line 1152, in send_message
    data = yield from self.http.send_message(channel_id, content, guild_id=guild_id, tts=tts, embed=embed)
  File "lib\discord\http.py", line 196, in request
    raise Forbidden(r, data)
discord.errors.Forbidden: FORBIDDEN (status code: 403): Missing Permissions
[08/05/2017 00:24] ERROR red on_command_error 369: Exception in command 'stop'
Traceback (most recent call last):
  File "lib\discord\ext\commands\core.py", line 50, in wrapped
    ret = yield from coro(*args, **kwargs)
  File "C:\Bot\Red-DiscordBot\cogs\audio.py", line 1896, in stop
    await self.bot.say("You can't stop music when there are other"
  File "lib\discord\ext\commands\bot.py", line 309, in _augmented_msg
    msg = yield from coro
  File "red.py", line 92, in send_message
    return await super().send_message(*args, **kwargs)
  File "lib\discord\client.py", line 1152, in send_message
    data = yield from self.http.send_message(channel_id, content, guild_id=guild_id, tts=tts, embed=embed)
  File "lib\discord\http.py", line 196, in request
    raise Forbidden(r, data)
discord.errors.Forbidden: FORBIDDEN (status code: 403): Missing Permissions
[11/05/2017 04:15] ERROR red on_command_error 369: Exception in command 'play'
Traceback (most recent call last):
  File "lib\discord\ext\commands\core.py", line 50, in wrapped
    ret = yield from coro(*args, **kwargs)
  File "C:\Bot\Red-DiscordBot\cogs\audio.py", line 1338, in play
    await ctx.invoke(self._queue, url=url)
  File "lib\discord\ext\commands\context.py", line 112, in invoke
    ret = yield from command.callback(*arguments, **kwargs)
  File "C:\Bot\Red-DiscordBot\cogs\audio.py", line 1665, in _queue
    await self.bot.say("Queued.")
  File "lib\discord\ext\commands\bot.py", line 309, in _augmented_msg
    msg = yield from coro
  File "red.py", line 92, in send_message
    return await super().send_message(*args, **kwargs)
  File "lib\discord\client.py", line 1152, in send_message
    data = yield from self.http.send_message(channel_id, content, guild_id=guild_id, tts=tts, embed=embed)
  File "lib\discord\http.py", line 196, in request
    raise Forbidden(r, data)
discord.errors.Forbidden: FORBIDDEN (status code: 403): Missing Permissions
[11/05/2017 04:16] ERROR red on_command_error 369: Exception in command 'skip'
Traceback (most recent call last):
  File "lib\discord\ext\commands\core.py", line 50, in wrapped
    ret = yield from coro(*args, **kwargs)
  File "C:\Bot\Red-DiscordBot\cogs\audio.py", line 1816, in skip
    await self.bot.reply(reply)
  File "lib\discord\ext\commands\bot.py", line 309, in _augmented_msg
    msg = yield from coro
  File "red.py", line 92, in send_message
    return await super().send_message(*args, **kwargs)
  File "lib\discord\client.py", line 1152, in send_message
    data = yield from self.http.send_message(channel_id, content, guild_id=guild_id, tts=tts, embed=embed)
  File "lib\discord\http.py", line 196, in request
    raise Forbidden(r, data)
discord.errors.Forbidden: FORBIDDEN (status code: 403): Missing Permissions
[11/05/2017 04:16] ERROR red on_command_error 369: Exception in command 'skip'
Traceback (most recent call last):
  File "lib\discord\ext\commands\core.py", line 50, in wrapped
    ret = yield from coro(*args, **kwargs)
  File "C:\Bot\Red-DiscordBot\cogs\audio.py", line 1790, in skip
    await self.bot.say("Skipping...")
  File "lib\discord\ext\commands\bot.py", line 309, in _augmented_msg
    msg = yield from coro
  File "red.py", line 92, in send_message
    return await super().send_message(*args, **kwargs)
  File "lib\discord\client.py", line 1152, in send_message
    data = yield from self.http.send_message(channel_id, content, guild_id=guild_id, tts=tts, embed=embed)
  File "lib\discord\http.py", line 196, in request
    raise Forbidden(r, data)
discord.errors.Forbidden: FORBIDDEN (status code: 403): Missing Permissions
[11/05/2017 04:17] ERROR red on_command_error 369: Exception in command 'play'
Traceback (most recent call last):
  File "lib\discord\ext\commands\core.py", line 50, in wrapped
    ret = yield from coro(*args, **kwargs)
  File "C:\Bot\Red-DiscordBot\cogs\audio.py", line 1338, in play
    await ctx.invoke(self._queue, url=url)
  File "lib\discord\ext\commands\context.py", line 112, in invoke
    ret = yield from command.callback(*arguments, **kwargs)
  File "C:\Bot\Red-DiscordBot\cogs\audio.py", line 1665, in _queue
    await self.bot.say("Queued.")
  File "lib\discord\ext\commands\bot.py", line 309, in _augmented_msg
    msg = yield from coro
  File "red.py", line 92, in send_message
    return await super().send_message(*args, **kwargs)
  File "lib\discord\client.py", line 1152, in send_message
    data = yield from self.http.send_message(channel_id, content, guild_id=guild_id, tts=tts, embed=embed)
  File "lib\discord\http.py", line 196, in request
    raise Forbidden(r, data)
discord.errors.Forbidden: FORBIDDEN (status code: 403): Missing Permissions
[11/05/2017 05:04] ERROR red on_command_error 369: Exception in command 'play'
Traceback (most recent call last):
  File "lib\discord\ext\commands\core.py", line 50, in wrapped
    ret = yield from coro(*args, **kwargs)
  File "C:\Bot\Red-DiscordBot\cogs\audio.py", line 1338, in play
    await ctx.invoke(self._queue, url=url)
  File "lib\discord\ext\commands\context.py", line 112, in invoke
    ret = yield from command.callback(*arguments, **kwargs)
  File "C:\Bot\Red-DiscordBot\cogs\audio.py", line 1665, in _queue
    await self.bot.say("Queued.")
  File "lib\discord\ext\commands\bot.py", line 309, in _augmented_msg
    msg = yield from coro
  File "red.py", line 92, in send_message
    return await super().send_message(*args, **kwargs)
  File "lib\discord\client.py", line 1152, in send_message
    data = yield from self.http.send_message(channel_id, content, guild_id=guild_id, tts=tts, embed=embed)
  File "lib\discord\http.py", line 196, in request
    raise Forbidden(r, data)
discord.errors.Forbidden: FORBIDDEN (status code: 403): Missing Permissions
[11/05/2017 05:04] ERROR red on_command_error 369: Exception in command 'skip'
Traceback (most recent call last):
  File "lib\discord\ext\commands\core.py", line 50, in wrapped
    ret = yield from coro(*args, **kwargs)
  File "C:\Bot\Red-DiscordBot\cogs\audio.py", line 1816, in skip
    await self.bot.reply(reply)
  File "lib\discord\ext\commands\bot.py", line 309, in _augmented_msg
    msg = yield from coro
  File "red.py", line 92, in send_message
    return await super().send_message(*args, **kwargs)
  File "lib\discord\client.py", line 1152, in send_message
    data = yield from self.http.send_message(channel_id, content, guild_id=guild_id, tts=tts, embed=embed)
  File "lib\discord\http.py", line 196, in request
    raise Forbidden(r, data)
discord.errors.Forbidden: FORBIDDEN (status code: 403): Missing Permissions
[11/05/2017 05:04] ERROR red on_command_error 369: Exception in command 'skip'
Traceback (most recent call last):
  File "lib\discord\ext\commands\core.py", line 50, in wrapped
    ret = yield from coro(*args, **kwargs)
  File "C:\Bot\Red-DiscordBot\cogs\audio.py", line 1790, in skip
    await self.bot.say("Skipping...")
  File "lib\discord\ext\commands\bot.py", line 309, in _augmented_msg
    msg = yield from coro
  File "red.py", line 92, in send_message
    return await super().send_message(*args, **kwargs)
  File "lib\discord\client.py", line 1152, in send_message
    data = yield from self.http.send_message(channel_id, content, guild_id=guild_id, tts=tts, embed=embed)
  File "lib\discord\http.py", line 196, in request
    raise Forbidden(r, data)
discord.errors.Forbidden: FORBIDDEN (status code: 403): Missing Permissions
[11/05/2017 05:04] ERROR red on_command_error 369: Exception in command 'skip'
Traceback (most recent call last):
  File "lib\discord\ext\commands\core.py", line 50, in wrapped
    ret = yield from coro(*args, **kwargs)
  File "C:\Bot\Red-DiscordBot\cogs\audio.py", line 1818, in skip
    await self.bot.say("You need to be in the voice channel to skip the music.")
  File "lib\discord\ext\commands\bot.py", line 309, in _augmented_msg
    msg = yield from coro
  File "red.py", line 92, in send_message
    return await super().send_message(*args, **kwargs)
  File "lib\discord\client.py", line 1152, in send_message
    data = yield from self.http.send_message(channel_id, content, guild_id=guild_id, tts=tts, embed=embed)
  File "lib\discord\http.py", line 196, in request
    raise Forbidden(r, data)
discord.errors.Forbidden: FORBIDDEN (status code: 403): Missing Permissions
[11/05/2017 05:05] ERROR red on_command_error 369: Exception in command 'skip'
Traceback (most recent call last):
  File "lib\discord\ext\commands\core.py", line 50, in wrapped
    ret = yield from coro(*args, **kwargs)
  File "C:\Bot\Red-DiscordBot\cogs\audio.py", line 1790, in skip
    await self.bot.say("Skipping...")
  File "lib\discord\ext\commands\bot.py", line 309, in _augmented_msg
    msg = yield from coro
  File "red.py", line 92, in send_message
    return await super().send_message(*args, **kwargs)
  File "lib\discord\client.py", line 1152, in send_message
    data = yield from self.http.send_message(channel_id, content, guild_id=guild_id, tts=tts, embed=embed)
  File "lib\discord\http.py", line 196, in request
    raise Forbidden(r, data)
discord.errors.Forbidden: FORBIDDEN (status code: 403): Missing Permissions
[11/05/2017 05:08] ERROR red on_command_error 369: Exception in command 'skip'
Traceback (most recent call last):
  File "lib\discord\ext\commands\core.py", line 50, in wrapped
    ret = yield from coro(*args, **kwargs)
  File "C:\Bot\Red-DiscordBot\cogs\audio.py", line 1790, in skip
    await self.bot.say("Skipping...")
  File "lib\discord\ext\commands\bot.py", line 309, in _augmented_msg
    msg = yield from coro
  File "red.py", line 92, in send_message
    return await super().send_message(*args, **kwargs)
  File "lib\discord\client.py", line 1152, in send_message
    data = yield from self.http.send_message(channel_id, content, guild_id=guild_id, tts=tts, embed=embed)
  File "lib\discord\http.py", line 196, in request
    raise Forbidden(r, data)
discord.errors.Forbidden: FORBIDDEN (status code: 403): Missing Permissions
[11/05/2017 05:08] ERROR red on_command_error 369: Exception in command 'skip'
Traceback (most recent call last):
  File "lib\discord\ext\commands\core.py", line 50, in wrapped
    ret = yield from coro(*args, **kwargs)
  File "C:\Bot\Red-DiscordBot\cogs\audio.py", line 1790, in skip
    await self.bot.say("Skipping...")
  File "lib\discord\ext\commands\bot.py", line 309, in _augmented_msg
    msg = yield from coro
  File "red.py", line 92, in send_message
    return await super().send_message(*args, **kwargs)
  File "lib\discord\client.py", line 1152, in send_message
    data = yield from self.http.send_message(channel_id, content, guild_id=guild_id, tts=tts, embed=embed)
  File "lib\discord\http.py", line 196, in request
    raise Forbidden(r, data)
discord.errors.Forbidden: FORBIDDEN (status code: 403): Missing Permissions
[11/05/2017 05:21] ERROR red on_command_error 369: Exception in command 'skip'
Traceback (most recent call last):
  File "lib\discord\ext\commands\core.py", line 50, in wrapped
    ret = yield from coro(*args, **kwargs)
  File "C:\Bot\Red-DiscordBot\cogs\audio.py", line 1790, in skip
    await self.bot.say("Skipping...")
  File "lib\discord\ext\commands\bot.py", line 309, in _augmented_msg
    msg = yield from coro
  File "red.py", line 92, in send_message
    return await super().send_message(*args, **kwargs)
  File "lib\discord\client.py", line 1152, in send_message
    data = yield from self.http.send_message(channel_id, content, guild_id=guild_id, tts=tts, embed=embed)
  File "lib\discord\http.py", line 196, in request
    raise Forbidden(r, data)
discord.errors.Forbidden: FORBIDDEN (status code: 403): Missing Permissions
[11/05/2017 07:31] ERROR red on_command_error 369: Exception in command 'pause'
Traceback (most recent call last):
  File "lib\discord\ext\commands\core.py", line 50, in wrapped
    ret = yield from coro(*args, **kwargs)
  File "C:\Bot\Red-DiscordBot\cogs\audio.py", line 1323, in pause
    await self.bot.say("Paused.")
  File "lib\discord\ext\commands\bot.py", line 309, in _augmented_msg
    msg = yield from coro
  File "red.py", line 92, in send_message
    return await super().send_message(*args, **kwargs)
  File "lib\discord\client.py", line 1152, in send_message
    data = yield from self.http.send_message(channel_id, content, guild_id=guild_id, tts=tts, embed=embed)
  File "lib\discord\http.py", line 196, in request
    raise Forbidden(r, data)
discord.errors.Forbidden: FORBIDDEN (status code: 403): Missing Permissions
[11/05/2017 08:51] ERROR red on_command_error 369: Exception in command 'play'
Traceback (most recent call last):
  File "lib\discord\ext\commands\core.py", line 50, in wrapped
    ret = yield from coro(*args, **kwargs)
  File "C:\Bot\Red-DiscordBot\cogs\audio.py", line 1338, in play
    await ctx.invoke(self._queue, url=url)
  File "lib\discord\ext\commands\context.py", line 112, in invoke
    ret = yield from command.callback(*arguments, **kwargs)
  File "C:\Bot\Red-DiscordBot\cogs\audio.py", line 1665, in _queue
    await self.bot.say("Queued.")
  File "lib\discord\ext\commands\bot.py", line 309, in _augmented_msg
    msg = yield from coro
  File "red.py", line 92, in send_message
    return await super().send_message(*args, **kwargs)
  File "lib\discord\client.py", line 1152, in send_message
    data = yield from self.http.send_message(channel_id, content, guild_id=guild_id, tts=tts, embed=embed)
  File "lib\discord\http.py", line 196, in request
    raise Forbidden(r, data)
discord.errors.Forbidden: FORBIDDEN (status code: 403): Missing Permissions
[11/05/2017 13:51] ERROR red on_command_error 369: Exception in command 'trivia list'
Traceback (most recent call last):
  File "lib\discord\ext\commands\core.py", line 50, in wrapped
    ret = yield from coro(*args, **kwargs)
  File "C:\Bot\Red-DiscordBot\cogs\trivia.py", line 148, in trivia_list
    await self.bot.say(msg)
  File "lib\discord\ext\commands\bot.py", line 309, in _augmented_msg
    msg = yield from coro
  File "red.py", line 92, in send_message
    return await super().send_message(*args, **kwargs)
  File "lib\discord\client.py", line 1152, in send_message
    data = yield from self.http.send_message(channel_id, content, guild_id=guild_id, tts=tts, embed=embed)
  File "lib\discord\http.py", line 196, in request
    raise Forbidden(r, data)
discord.errors.Forbidden: FORBIDDEN (status code: 403): Missing Permissions
